<?xml version='1.0' encoding='utf-8'?>
<robot name="tianyi2_urdf">
  <link name="base">
    <inertial>
      <origin xyz="-0.00067 -0.002625 0.150395" rpy="0 0 0" />
      <mass value="47.555667" />
      <inertia ixx="1.277779" ixy="-0.001232" ixz="-0.093599" iyy="1.293166" iyz="0.0036" izz="1.385346" />
    </inertial>
    <visual>
      <origin xyz="0 0 0" rpy="0 0 0" />
      <geometry>
        <mesh filename="package://tianyi2_urdf/meshes/base.STL" />
      </geometry>
      <material name="">
        <color rgba="0.752941176470588 0.752941176470588 0.752941176470588 1" />
      </material>
    </visual>
    <collision>
      <origin xyz="0 0 0" rpy="0 0 0" />
      <geometry>
        <mesh filename="package://tianyi2_urdf/meshes/base.STL" />
      </geometry>
    </collision>
  </link>
  <link name="first_leg_pitch_link">
    <inertial>
      <origin xyz="-0.105847 -0.000632 0.041305" rpy="0 0 0" />
      <mass value="2.460134" />
      <inertia ixx="0.012918" ixy="0.000516" ixz="0.0066" iyy="0.028707" iyz="-0.000254" izz="0.027239" />
    </inertial>
    <visual>
      <origin xyz="0 0 0" rpy="0 0 0" />
      <geometry>
        <mesh filename="package://tianyi2_urdf/meshes/first_leg_pitch_link.STL" />
      </geometry>
      <material name="">
        <color rgba="0.752941176470588 0.752941176470588 0.752941176470588 1" />
      </material>
    </visual>
    <collision>
      <origin xyz="0 0 0" rpy="0 0 0" />
      <geometry>
        <mesh filename="package://tianyi2_urdf/meshes/first_leg_pitch_link.STL" />
      </geometry>
    </collision>
  </link>
  <joint name="first_leg_pitch_joint" type="revolute">
    <origin xyz="0.049182 0 0.37" rpy="0 0 0" />
    <parent link="base" />
    <child link="first_leg_pitch_link" />
    <axis xyz="0 1 0" />
    <limit lower="-0.41887902047863906" upper="1.0471975511965976" effort="332.0" velocity="3.9269908169872414" />
  </joint>
  <link name="second_leg_pitch_link">
    <inertial>
      <origin xyz="0.056775 0.000389 0.045258" rpy="0 0 0" />
      <mass value="2.430846" />
      <inertia ixx="0.011853" ixy="4.6e-05" ixz="-0.009109" iyy="0.025086" iyz="5.6e-05" izz="0.022169" />
    </inertial>
    <visual>
      <origin xyz="0 0 0" rpy="0 0 0" />
      <geometry>
        <mesh filename="package://tianyi2_urdf/meshes/second_leg_pitch_link.STL" />
      </geometry>
      <material name="">
        <color rgba="0.752941176470588 0.752941176470588 0.752941176470588 1" />
      </material>
    </visual>
    <collision>
      <origin xyz="0 0 0" rpy="0 0 0" />
      <geometry>
        <mesh filename="package://tianyi2_urdf/meshes/second_leg_pitch_link.STL" />
      </geometry>
    </collision>
  </link>
  <joint name="second_leg_pitch_joint" type="revolute">
    <origin xyz="-0.20785 0 0.12" rpy="0 0 0" />
    <parent link="first_leg_pitch_link" />
    <child link="second_leg_pitch_link" />
    <axis xyz="0 1 0" />
    <limit lower="-0.5061454830783556" upper="1.7453292519943295" effort="332.0" velocity="3.9269908169872414" />
  </joint>
  <link name="waist_pitch_link">
    <inertial>
      <origin xyz="8e-06 0.012369 0.001276" rpy="0 0 0" />
      <mass value="3.38238" />
      <inertia ixx="0.005589" ixy="1e-06" ixz="-1e-06" iyy="0.006064" iyz="4.9e-05" izz="0.005334" />
    </inertial>
    <visual>
      <origin xyz="0 0 0" rpy="0 0 0" />
      <geometry>
        <mesh filename="package://tianyi2_urdf/meshes/waist_pitch_link.STL" />
      </geometry>
      <material name="">
        <color rgba="0.752941176470588 0.752941176470588 0.752941176470588 1" />
      </material>
    </visual>
    <collision>
      <origin xyz="0 0 0" rpy="0 0 0" />
      <geometry>
        <mesh filename="package://tianyi2_urdf/meshes/waist_pitch_link.STL" />
      </geometry>
    </collision>
  </link>
  <joint name="waist_pitch_joint" type="revolute">
    <origin xyz="0.20785 0 0.12" rpy="0 0 0" />
    <parent link="second_leg_pitch_link" />
    <child link="waist_pitch_link" />
    <axis xyz="0 1 0" />
    <limit lower="-2.0943951023931953" upper="0.7853981633974483" effort="332.0" velocity="3.9269908169872414" />
  </joint>
  <link name="body_yaw_link">
    <inertial>
      <origin xyz="0.009196 -0.000592 0.251379" rpy="0 0 0" />
      <mass value="13.795395" />
      <inertia ixx="0.372395" ixy="0.000248" ixz="0.001337" iyy="0.331609" iyz="0.000779" izz="0.127753" />
    </inertial>
    <visual>
      <origin xyz="0 0 0" rpy="0 0 0" />
      <geometry>
        <mesh filename="package://tianyi2_urdf/meshes/body_yaw_link.STL" />
      </geometry>
      <material name="">
        <color rgba="0.752941176470588 0.752941176470588 0.752941176470588 1" />
      </material>
    </visual>
    <collision>
      <origin xyz="0 0 0" rpy="0 0 0" />
      <geometry>
        <mesh filename="package://tianyi2_urdf/meshes/body_yaw_link.STL" />
      </geometry>
    </collision>
  </link>
  <joint name="body_yaw_joint" type="revolute">
    <origin xyz="0 0 0.07" rpy="0 0 0" />
    <parent link="waist_pitch_link" />
    <child link="body_yaw_link" />
    <axis xyz="0 0 1" />
    <limit lower="-2.9670597283903604" upper="3.141592653589793" effort="143.0" velocity="4.71238898038469" />
  </joint>
  <link name="head_yaw_link">
    <inertial>
      <origin xyz="-0.000202 0.000454 0.007248" rpy="0 0 0" />
      <mass value="0.088397" />
      <inertia ixx="9.5e-05" ixy="-1e-06" ixz="-3e-06" iyy="7.6e-05" iyz="-3e-06" izz="0.000106" />
    </inertial>
    <visual>
      <origin xyz="0 0 0" rpy="0 0 0" />
      <geometry>
        <mesh filename="package://tianyi2_urdf/meshes/head_yaw_link.STL" />
      </geometry>
      <material name="">
        <color rgba="0.752941176470588 0.752941176470588 0.752941176470588 1" />
      </material>
    </visual>
    <collision>
      <origin xyz="0 0 0" rpy="0 0 0" />
      <geometry>
        <mesh filename="package://tianyi2_urdf/meshes/head_yaw_link.STL" />
      </geometry>
    </collision>
  </link>
  <joint name="head_yaw_joint" type="revolute">
    <origin xyz="-0.002 0 0.56508" rpy="0 0 0" />
    <parent link="body_yaw_link" />
    <child link="head_yaw_link" />
    <axis xyz="0 0 1" />
    <limit lower="-1.5707963267948966" upper="1.5707963267948966" effort="6.3" velocity="7.5398223686155035" />
  </joint>
  <link name="head_pitch_link">
    <inertial>
      <origin xyz="-0.000274 0.004118 2.3e-05" rpy="0 0 0" />
      <mass value="0.23046" />
      <inertia ixx="9.2e-05" ixy="1e-06" ixz="-1e-06" iyy="5.4e-05" iyz="0.0" izz="9.5e-05" />
    </inertial>
    <visual>
      <origin xyz="0 0 0" rpy="0 0 0" />
      <geometry>
        <mesh filename="package://tianyi2_urdf/meshes/head_pitch_link.STL" />
      </geometry>
      <material name="">
        <color rgba="0.752941176470588 0.752941176470588 0.752941176470588 1" />
      </material>
    </visual>
    <collision>
      <origin xyz="0 0 0" rpy="0 0 0" />
      <geometry>
        <mesh filename="package://tianyi2_urdf/meshes/head_pitch_link.STL" />
      </geometry>
    </collision>
  </link>
  <joint name="head_pitch_joint" type="revolute">
    <origin xyz="0.01455 0 0.0304" rpy="0 0.2618 0" />
    <parent link="head_yaw_link" />
    <child link="head_pitch_link" />
    <axis xyz="0 1 0" />
    <limit lower="-0.4363323129985824" upper="0.4363323129985824" effort="6.3" velocity="7.5398223686155035" />
  </joint>
  <link name="head_roll_link">
    <inertial>
      <origin xyz="0.022467 0.001208 0.053952" rpy="0 0 0" />
      <mass value="0.844627" />
      <inertia ixx="0.00235" ixy="3.8e-05" ixz="0.000436" iyy="0.003365" iyz="6e-06" izz="0.002875" />
    </inertial>
    <visual>
      <origin xyz="0 0 0" rpy="0 0 0" />
      <geometry>
        <mesh filename="package://tianyi2_urdf/meshes/head_roll_link.STL" />
      </geometry>
      <material name="">
        <color rgba="0.752941176470588 0.752941176470588 0.752941176470588 1" />
      </material>
    </visual>
    <collision>
      <origin xyz="0 0 0" rpy="0 0 0" />
      <geometry>
        <mesh filename="package://tianyi2_urdf/meshes/head_roll_link.STL" />
      </geometry>
    </collision>
  </link>
  <joint name="head_roll_joint" type="revolute">
    <origin xyz="0 0 0" rpy="0 0 0" />
    <parent link="head_pitch_link" />
    <child link="head_roll_link" />
    <axis xyz="1 0 0" />
    <limit lower="-0.4537856055185257" upper="0.4537856055185257" effort="6.3" velocity="7.5398223686155035" />
  </joint>
  <link name="camera_head_link">
    <inertial>
      <origin xyz="0.010986 -0.000307 -0.016475" rpy="0 0 0" />
      <mass value="0.1" />
      <inertia ixx="1.6e-05" ixy="0.0" ixz="0.0" iyy="8e-05" iyz="0.0" izz="7.7e-05" />
    </inertial>
    <visual>
      <origin xyz="0 0 0" rpy="0 0 0" />
      <geometry>
        <mesh filename="package://tianyi2_urdf/meshes/camera_head_link.STL" />
      </geometry>
      <material name="">
        <color rgba="0.752941176470588 0.752941176470588 0.752941176470588 1" />
      </material>
    </visual>
    <collision>
      <origin xyz="0 0 0" rpy="0 0 0" />
      <geometry>
        <mesh filename="package://tianyi2_urdf/meshes/camera_head_link.STL" />
      </geometry>
    </collision>
  </link>
  <joint name="camera_head_joint" type="fixed">
    <origin xyz="0.075288 0.010935 0.07441" rpy="-1.8326 0 -1.5708" />
    <parent link="head_roll_link" />
    <child link="camera_head_link" />
    <axis xyz="0 0 0" />
  </joint>
  <link name="shoulder_pitch_l_link">
    <inertial>
      <origin xyz="0.007494 0.064184 -2e-05" rpy="0 0 0" />
      <mass value="1.032698" />
      <inertia ixx="0.001025" ixy="-2.7e-05" ixz="-1e-06" iyy="0.001078" iyz="0.0" izz="0.001247" />
    </inertial>
    <visual>
      <origin xyz="0 0 0" rpy="0 0 0" />
      <geometry>
        <mesh filename="package://tianyi2_urdf/meshes/shoulder_pitch_l_link.STL" />
      </geometry>
      <material name="">
        <color rgba="0.752941176470588 0.752941176470588 0.752941176470588 1" />
      </material>
    </visual>
    <collision>
      <origin xyz="0 0 0" rpy="0 0 0" />
      <geometry>
        <mesh filename="package://tianyi2_urdf/meshes/shoulder_pitch_l_link.STL" />
      </geometry>
    </collision>
  </link>
  <joint name="shoulder_pitch_l_joint" type="revolute">
    <origin xyz="0 0.14539 0.37721" rpy="0.087266 0 0" />
    <parent link="body_yaw_link" />
    <child link="shoulder_pitch_l_link" />
    <axis xyz="0 1 0" />
    <limit lower="-2.9670597283903604" upper="2.9670597283903604" effort="91.0" velocity="9.215338450530059" />
  </joint>
  <link name="shoulder_roll_l_link">
    <inertial>
      <origin xyz="0.002389 0.002259 -0.048236" rpy="0 0 0" />
      <mass value="0.440997" />
      <inertia ixx="0.001001" ixy="-4e-06" ixz="-2.5e-05" iyy="0.001313" iyz="-1.4e-05" izz="0.000911" />
    </inertial>
    <visual>
      <origin xyz="0 0 0" rpy="0 0 0" />
      <geometry>
        <mesh filename="package://tianyi2_urdf/meshes/shoulder_roll_l_link.STL" />
      </geometry>
      <material name="">
        <color rgba="0.752941176470588 0.752941176470588 0.752941176470588 1" />
      </material>
    </visual>
    <collision>
      <origin xyz="0 0 0" rpy="0 0 0" />
      <geometry>
        <mesh filename="package://tianyi2_urdf/meshes/shoulder_roll_l_link.STL" />
      </geometry>
    </collision>
  </link>
  <joint name="shoulder_roll_l_joint" type="revolute">
    <origin xyz="0 0.068 0" rpy="0 0 0" />
    <parent link="shoulder_pitch_l_link" />
    <child link="shoulder_roll_l_link" />
    <axis xyz="1 0 0" />
    <limit lower="-1.0471975511965976" upper="1.8325957145940461" effort="95.0" velocity="3.979350694547071" />
  </joint>
  <link name="shoulder_yaw_l_link">
    <inertial>
      <origin xyz="0.008319 0.002686 -0.112525" rpy="0 0 0" />
      <mass value="1.365033" />
      <inertia ixx="0.009637" ixy="-5.7e-05" ixz="0.00095" iyy="0.0096" iyz="0.000339" izz="0.001331" />
    </inertial>
    <visual>
      <origin xyz="0 0 0" rpy="0 0 0" />
      <geometry>
        <mesh filename="package://tianyi2_urdf/meshes/shoulder_yaw_l_link.STL" />
      </geometry>
      <material name="">
        <color rgba="0.752941176470588 0.752941176470588 0.752941176470588 1" />
      </material>
    </visual>
    <collision>
      <origin xyz="0 0 0" rpy="0 0 0" />
      <geometry>
        <mesh filename="package://tianyi2_urdf/meshes/shoulder_yaw_l_link.STL" />
      </geometry>
    </collision>
  </link>
  <joint name="shoulder_yaw_l_joint" type="revolute">
    <origin xyz="0 0 -0.1025" rpy="0 0 0" />
    <parent link="shoulder_roll_l_link" />
    <child link="shoulder_yaw_l_link" />
    <axis xyz="0 0 1" />
    <limit lower="-2.9670597283903604" upper="2.9670597283903604" effort="35.0" velocity="5.235987755982989" />
  </joint>
  <link name="elbow_pitch_l_link">
    <inertial>
      <origin xyz="-0.014694 -7.2e-05 -0.026081" rpy="0 0 0" />
      <mass value="0.246311" />
      <inertia ixx="0.000381" ixy="1e-06" ixz="-1.2e-05" iyy="0.000222" iyz="2e-06" izz="0.000401" />
    </inertial>
    <visual>
      <origin xyz="0 0 0" rpy="0 0 0" />
      <geometry>
        <mesh filename="package://tianyi2_urdf/meshes/elbow_pitch_l_link.STL" />
      </geometry>
      <material name="">
        <color rgba="0.752941176470588 0.752941176470588 0.752941176470588 1" />
      </material>
    </visual>
    <collision>
      <origin xyz="0 0 0" rpy="0 0 0" />
      <geometry>
        <mesh filename="package://tianyi2_urdf/meshes/elbow_pitch_l_link.STL" />
      </geometry>
    </collision>
  </link>
  <joint name="elbow_pitch_l_joint" type="revolute">
    <origin xyz="0.02 0 -0.1975" rpy="0 0 0" />
    <parent link="shoulder_yaw_l_link" />
    <child link="elbow_pitch_l_link" />
    <axis xyz="0 1 0" />
    <limit lower="-2.6179938779914944" upper="0.2617993877991494" effort="35.0" velocity="5.235987755982989" />
  </joint>
  <link name="elbow_yaw_l_link">
    <inertial>
      <origin xyz="0.000158 0.001503 -0.069535" rpy="0 0 0" />
      <mass value="0.986828" />
      <inertia ixx="0.003108" ixy="-1e-06" ixz="8e-06" iyy="0.003035" iyz="8.9e-05" izz="0.00058" />
    </inertial>
    <visual>
      <origin xyz="0 0 0" rpy="0 0 0" />
      <geometry>
        <mesh filename="package://tianyi2_urdf/meshes/elbow_yaw_l_link.STL" />
      </geometry>
      <material name="">
        <color rgba="0.752941176470588 0.752941176470588 0.752941176470588 1" />
      </material>
    </visual>
    <collision>
      <origin xyz="0 0 0" rpy="0 0 0" />
      <geometry>
        <mesh filename="package://tianyi2_urdf/meshes/elbow_yaw_l_link.STL" />
      </geometry>
    </collision>
  </link>
  <joint name="elbow_yaw_l_joint" type="revolute">
    <origin xyz="-0.02 0 -0.0543" rpy="0 0 0" />
    <parent link="elbow_pitch_l_link" />
    <child link="elbow_yaw_l_link" />
    <axis xyz="0 0 1" />
    <limit lower="-2.9670597283903604" upper="2.9670597283903604" effort="24.0" velocity="10.471975511965978" />
  </joint>
  <link name="wrist_pitch_l_link">
    <inertial>
      <origin xyz="0.005362 0.00064 -0.018812" rpy="0 0 0" />
      <mass value="0.262007" />
      <inertia ixx="7.1e-05" ixy="-3e-06" ixz="-2e-06" iyy="0.000112" iyz="-3e-06" izz="0.000111" />
    </inertial>
    <visual>
      <origin xyz="0 0 0" rpy="0 0 0" />
      <geometry>
        <mesh filename="package://tianyi2_urdf/meshes/wrist_pitch_l_link.STL" />
      </geometry>
      <material name="">
        <color rgba="0.752941176470588 0.752941176470588 0.752941176470588 1" />
      </material>
    </visual>
    <collision>
      <origin xyz="0 0 0" rpy="0 0 0" />
      <geometry>
        <mesh filename="package://tianyi2_urdf/meshes/wrist_pitch_l_link.STL" />
      </geometry>
    </collision>
  </link>
  <joint name="wrist_pitch_l_joint" type="revolute">
    <origin xyz="0 0.002 -0.1887" rpy="0 0 0" />
    <parent link="elbow_yaw_l_link" />
    <child link="wrist_pitch_l_link" />
    <axis xyz="0 1 0" />
    <limit lower="-1.3089969389957472" upper="1.6580627893946132" effort="6.3" velocity="7.5398223686155035" />
  </joint>
  <link name="wrist_roll_l_link">
    <inertial>
      <origin xyz="0.000801 8.4e-05 -0.029302" rpy="0 0 0" />
      <mass value="0.131751" />
      <inertia ixx="6.9e-05" ixy="0.0" ixz="-1e-06" iyy="0.000116" iyz="0.0" izz="0.00011" />
    </inertial>
    <visual>
      <origin xyz="0 0 0" rpy="0 0 0" />
      <geometry>
        <mesh filename="package://tianyi2_urdf/meshes/wrist_roll_l_link.STL" />
      </geometry>
      <material name="">
        <color rgba="0.752941176470588 0.752941176470588 0.752941176470588 1" />
      </material>
    </visual>
    <collision>
      <origin xyz="0 0 0" rpy="0 0 0" />
      <geometry>
        <mesh filename="package://tianyi2_urdf/meshes/wrist_roll_l_link.STL" />
      </geometry>
    </collision>
  </link>
  <joint name="wrist_roll_l_joint" type="revolute">
    <origin xyz="5.0485E-05 0 -0.02" rpy="0 0 0" />
    <parent link="wrist_pitch_l_link" />
    <child link="wrist_roll_l_link" />
    <axis xyz="1 0 0" />
    <limit lower="-1.0471975511965976" upper="0.7853981633974483" effort="6.3" velocity="7.5398223686155035" />
  </joint>
  <link name="left_tcp_link">
    <inertial>
      <origin xyz="0.000238 0.000502 0.021714" rpy="0 0 0" />
      <mass value="0.252604" />
      <inertia ixx="0.000124" ixy="-2e-06" ixz="0.0" iyy="0.000119" iyz="0.0" izz="0.000132" />
    </inertial>
    <visual>
      <origin xyz="0 0 0" rpy="0 0 0" />
      <geometry>
        <mesh filename="package://tianyi2_urdf/meshes/left_tcp_link.STL" />
      </geometry>
      <material name="">
        <color rgba="0.752941176470588 0.752941176470588 0.752941176470588 1" />
      </material>
    </visual>
    <collision>
      <origin xyz="0 0 0" rpy="0 0 0" />
      <geometry>
        <mesh filename="package://tianyi2_urdf/meshes/left_tcp_link.STL" />
      </geometry>
    </collision>
  </link>
  <joint name="left_tcp_joint" type="fixed">
    <origin xyz="0 3.5454E-05 -0.084799" rpy="0 0 0" />
    <parent link="wrist_roll_l_link" />
    <child link="left_tcp_link" />
    <axis xyz="0 0 0" />
  </joint>
  <link name="shoulder_pitch_r_link">
    <inertial>
      <origin xyz="0.007494 -0.064184 -2e-05" rpy="0 0 0" />
      <mass value="1.032698" />
      <inertia ixx="0.001025" ixy="2.7e-05" ixz="-1e-06" iyy="0.001078" iyz="0.0" izz="0.001247" />
    </inertial>
    <visual>
      <origin xyz="0 0 0" rpy="0 0 0" />
      <geometry>
        <mesh filename="package://tianyi2_urdf/meshes/shoulder_pitch_r_link.STL" />
      </geometry>
      <material name="">
        <color rgba="0.752941176470588 0.752941176470588 0.752941176470588 1" />
      </material>
    </visual>
    <collision>
      <origin xyz="0 0 0" rpy="0 0 0" />
      <geometry>
        <mesh filename="package://tianyi2_urdf/meshes/shoulder_pitch_r_link.STL" />
      </geometry>
    </collision>
  </link>
  <joint name="shoulder_pitch_r_joint" type="revolute">
    <origin xyz="0 -0.14539 0.37721" rpy="-0.087266 0 0" />
    <parent link="body_yaw_link" />
    <child link="shoulder_pitch_r_link" />
    <axis xyz="0 1 0" />
    <limit lower="-2.9670597283903604" upper="2.9670597283903604" effort="91.0" velocity="9.215338450530059" />
  </joint>
  <link name="shoulder_roll_r_link">
    <inertial>
      <origin xyz="0.002389 -0.002259 -0.048236" rpy="0 0 0" />
      <mass value="0.440997" />
      <inertia ixx="0.001001" ixy="4e-06" ixz="-2.5e-05" iyy="0.001313" iyz="1.4e-05" izz="0.000911" />
    </inertial>
    <visual>
      <origin xyz="0 0 0" rpy="0 0 0" />
      <geometry>
        <mesh filename="package://tianyi2_urdf/meshes/shoulder_roll_r_link.STL" />
      </geometry>
      <material name="">
        <color rgba="0.752941176470588 0.752941176470588 0.752941176470588 1" />
      </material>
    </visual>
    <collision>
      <origin xyz="0 0 0" rpy="0 0 0" />
      <geometry>
        <mesh filename="package://tianyi2_urdf/meshes/shoulder_roll_r_link.STL" />
      </geometry>
    </collision>
  </link>
  <joint name="shoulder_roll_r_joint" type="revolute">
    <origin xyz="0 -0.068 0" rpy="0 0 0" />
    <parent link="shoulder_pitch_r_link" />
    <child link="shoulder_roll_r_link" />
    <axis xyz="1 0 0" />
    <limit lower="-1.8325957145940461" upper="1.0471975511965976" effort="95.0" velocity="3.979350694547071" />
  </joint>
  <link name="shoulder_yaw_r_link">
    <inertial>
      <origin xyz="0.008319 -0.002686 -0.112525" rpy="0 0 0" />
      <mass value="1.365033" />
      <inertia ixx="0.009637" ixy="5.7e-05" ixz="0.00095" iyy="0.0096" iyz="-0.000339" izz="0.001331" />
    </inertial>
    <visual>
      <origin xyz="0 0 0" rpy="0 0 0" />
      <geometry>
        <mesh filename="package://tianyi2_urdf/meshes/shoulder_yaw_r_link.STL" />
      </geometry>
      <material name="">
        <color rgba="0.752941176470588 0.752941176470588 0.752941176470588 1" />
      </material>
    </visual>
    <collision>
      <origin xyz="0 0 0" rpy="0 0 0" />
      <geometry>
        <mesh filename="package://tianyi2_urdf/meshes/shoulder_yaw_r_link.STL" />
      </geometry>
    </collision>
  </link>
  <joint name="shoulder_yaw_r_joint" type="revolute">
    <origin xyz="0 0 -0.1025" rpy="0 0 0" />
    <parent link="shoulder_roll_r_link" />
    <child link="shoulder_yaw_r_link" />
    <axis xyz="0 0 1" />
    <limit lower="-2.9670597283903604" upper="2.9670597283903604" effort="35.0" velocity="5.235987755982989" />
  </joint>
  <link name="elbow_pitch_r_link">
    <inertial>
      <origin xyz="-0.014694 7.2e-05 -0.026081" rpy="0 0 0" />
      <mass value="0.246311" />
      <inertia ixx="0.000381" ixy="-1e-06" ixz="-1.2e-05" iyy="0.000222" iyz="-2e-06" izz="0.000401" />
    </inertial>
    <visual>
      <origin xyz="0 0 0" rpy="0 0 0" />
      <geometry>
        <mesh filename="package://tianyi2_urdf/meshes/elbow_pitch_r_link.STL" />
      </geometry>
      <material name="">
        <color rgba="0.752941176470588 0.752941176470588 0.752941176470588 1" />
      </material>
    </visual>
    <collision>
      <origin xyz="0 0 0" rpy="0 0 0" />
      <geometry>
        <mesh filename="package://tianyi2_urdf/meshes/elbow_pitch_r_link.STL" />
      </geometry>
    </collision>
  </link>
  <joint name="elbow_pitch_r_joint" type="revolute">
    <origin xyz="0.02 0 -0.1975" rpy="0 0 0" />
    <parent link="shoulder_yaw_r_link" />
    <child link="elbow_pitch_r_link" />
    <axis xyz="0 1 0" />
    <limit lower="-2.6179938779914944" upper="0.2617993877991494" effort="35.0" velocity="5.235987755982989" />
  </joint>
  <link name="elbow_yaw_r_link">
    <inertial>
      <origin xyz="0.000158 -0.001503 -0.069535" rpy="0 0 0" />
      <mass value="0.986828" />
      <inertia ixx="0.003108" ixy="1e-06" ixz="8e-06" iyy="0.003035" iyz="-8.9e-05" izz="0.00058" />
    </inertial>
    <visual>
      <origin xyz="0 0 0" rpy="0 0 0" />
      <geometry>
        <mesh filename="package://tianyi2_urdf/meshes/elbow_yaw_r_link.STL" />
      </geometry>
      <material name="">
        <color rgba="0.752941176470588 0.752941176470588 0.752941176470588 1" />
      </material>
    </visual>
    <collision>
      <origin xyz="0 0 0" rpy="0 0 0" />
      <geometry>
        <mesh filename="package://tianyi2_urdf/meshes/elbow_yaw_r_link.STL" />
      </geometry>
    </collision>
  </link>
  <joint name="elbow_yaw_r_joint" type="revolute">
    <origin xyz="-0.02 0 -0.0543" rpy="0 0 0" />
    <parent link="elbow_pitch_r_link" />
    <child link="elbow_yaw_r_link" />
    <axis xyz="0 0 1" />
    <limit lower="-2.9670597283903604" upper="2.9670597283903604" effort="24.0" velocity="10.471975511965978" />
  </joint>
  <link name="wrist_pitch_r_link">
    <inertial>
      <origin xyz="0.005362 -0.00064 -0.018812" rpy="0 0 0" />
      <mass value="0.262007" />
      <inertia ixx="7.1e-05" ixy="3e-06" ixz="-2e-06" iyy="0.000112" iyz="3e-06" izz="0.000111" />
    </inertial>
    <visual>
      <origin xyz="0 0 0" rpy="0 0 0" />
      <geometry>
        <mesh filename="package://tianyi2_urdf/meshes/wrist_pitch_r_link.STL" />
      </geometry>
      <material name="">
        <color rgba="0.752941176470588 0.752941176470588 0.752941176470588 1" />
      </material>
    </visual>
    <collision>
      <origin xyz="0 0 0" rpy="0 0 0" />
      <geometry>
        <mesh filename="package://tianyi2_urdf/meshes/wrist_pitch_r_link.STL" />
      </geometry>
    </collision>
  </link>
  <joint name="wrist_pitch_r_joint" type="revolute">
    <origin xyz="0 -0.002 -0.1887" rpy="0 0 0" />
    <parent link="elbow_yaw_r_link" />
    <child link="wrist_pitch_r_link" />
    <axis xyz="0 1 0" />
    <limit lower="-1.3089969389957472" upper="1.6580627893946132" effort="6.3" velocity="7.5398223686155035" />
  </joint>
  <link name="wrist_roll_r_link">
    <inertial>
      <origin xyz="0.000801 -8.4e-05 -0.029302" rpy="0 0 0" />
      <mass value="0.131751" />
      <inertia ixx="6.9e-05" ixy="0.0" ixz="-1e-06" iyy="0.000116" iyz="0.0" izz="0.00011" />
    </inertial>
    <visual>
      <origin xyz="0 0 0" rpy="0 0 0" />
      <geometry>
        <mesh filename="package://tianyi2_urdf/meshes/wrist_roll_r_link.STL" />
      </geometry>
      <material name="">
        <color rgba="0.752941176470588 0.752941176470588 0.752941176470588 1" />
      </material>
    </visual>
    <collision>
      <origin xyz="0 0 0" rpy="0 0 0" />
      <geometry>
        <mesh filename="package://tianyi2_urdf/meshes/wrist_roll_r_link.STL" />
      </geometry>
    </collision>
  </link>
  <joint name="wrist_roll_r_joint" type="revolute">
    <origin xyz="5.0485E-05 0 -0.02" rpy="0 0 0" />
    <parent link="wrist_pitch_r_link" />
    <child link="wrist_roll_r_link" />
    <axis xyz="1 0 0" />
    <limit lower="-0.7853981633974483" upper="1.0471975511965976" effort="6.3" velocity="7.5398223686155035" />
  </joint>
  <link name="right_tcp_link">
    <inertial>
      <origin xyz="0.000238 -0.000502 0.021714" rpy="0 0 0" />
      <mass value="0.252604" />
      <inertia ixx="0.000124" ixy="2e-06" ixz="0.0" iyy="0.000119" iyz="0.0" izz="0.000132" />
    </inertial>
    <visual>
      <origin xyz="0 0 0" rpy="0 0 0" />
      <geometry>
        <mesh filename="package://tianyi2_urdf/meshes/right_tcp_link.STL" />
      </geometry>
      <material name="">
        <color rgba="0.752941176470588 0.752941176470588 0.752941176470588 1" />
      </material>
    </visual>
    <collision>
      <origin xyz="0 0 0" rpy="0 0 0" />
      <geometry>
        <mesh filename="package://tianyi2_urdf/meshes/right_tcp_link.STL" />
      </geometry>
    </collision>
  </link>
  <joint name="right_tcp_joint" type="fixed">
    <origin xyz="0 -3.5405E-05 -0.084799" rpy="0 0 0" />
    <parent link="wrist_roll_r_link" />
    <child link="right_tcp_link" />
    <axis xyz="0 0 0" />
  </joint>
</robot>